Workbook

Sheet Capacidad del equipo
B3: Miembro (Rol) | C3: Capacidad Nominal | D3: Ceremonias Scrum | E3: Gestión y Coordinación (Rol) | F3: Imprevistos / Margen | G3: Capacidad Efectiva (h-p) | H3: Factor de enfoque real
B4: Jorge Acedo (PO) | C4: 6 | D4: 1.5 | E4: 1.5 | F4: 0.5 | G4: =C4-D4-E4-F4 -> 2.5 | H4: =G4/C4 -> 0.41666667
B5: Sergio Jiménez (SM) | C5: 6 | D5: 1.5 | E5: 1.5 | F5: 0.5 | G5: =C5-D5-E5-F5 -> 2.5 | H5: =G5/C5 -> 0.41666667
B6: Alfonso Canal (TL) | C6: 6 | D6: 1.5 | E6: 1 | F6: 0.5 | G6: =C6-D6-E6-F6 -> 3 | H6: =G6/C6 -> 0.5
B7: Elena Cancho (QA/DevOps) | C7: 6 | D7: 1.5 | E7: 0.5 | F7: 0.5 | G7: =C7-D7-E7-F7 -> 3.5 | H7: =G7/C7 -> 0.58333333
B8: Adolfo Lozano (Dev) | C8: 6 | D8: 1.5 | E8: 0 | F8: 0.5 | G8: =C8-D8-E8-F8 -> 4 | H8: =G8/C8 -> 0.66666667
B9: TOTAL EQUIPO | C9: =SUM(C4:C8) -> 30 | D9: =SUM(D4:D8) -> 7.5 | E9: =SUM(E4:E8) -> 4.5 | F9: =SUM(F4:F8) -> 2.5 | G9: =SUM(G4:G8) -> 15.5 | H9: =G9/C9 -> 0.51666667
B12: Capacidad del proyecto (6 sprints de 1 semana)
B13: Número de iteraciones (sprints) | C13: 6
B14: Capacidad efectiva equipo / semana (h-p) | C14: 15.5
B15: Capacidad efectiva TOTAL proyecto (h-p) | C15: =C13*C14 -> 93
B18: Tarifas por rol (€/h-p) — Corvalen Dynamics
B19: Miembro (Rol) | C19: Tarifa (€/h-p)
B20: Jorge Acedo (PO) | C20: 32
B21: Sergio Jiménez (SM) | C21: 30
B22: Alfonso Canal (TL) | C22: 42
B23: Elena Cancho (QA/DevOps) | C23: 34
B24: Adolfo Lozano (Dev) | C24: 28
B26: Tarifa media ponderada del equipo (€/h-p) | C26: =SUMPRODUCT(G4:G8, C20:C24) / G9 -> 33.032258

Sheet Product Backlog
B4: ID | C4: Épica | D4: Historia de Usuario | E4: Depende de | F4: Prioridad (MoSCoW) | G4: Estimación (h-p)
B5: US-001 | C5: EP-001 | D5: Buscar pieza por nombre o código para ver disponibilidad. | E5: - | F5: Must have | G5: 4.5
B6: US-002 | C6: EP-002 | D6: Solicitar pieza indicando tarea de mantenimiento asociada. | E6: US-001 | F6: Must have | G6: 7.5
B7: US-003 | C7: EP-004 | D7: Consultar el estado (pendiente/aceptada/entregada) de mis solicitudes. | E7: US-002 | F7: Must have | G7: 4.5
B8: US-004 | C8: EP-003 | D8: Ver listado de solicitudes pendientes en almacén. | E8: US-002 | F8: Must have | G8: 4.5
B9: US-005 | C9: EP-003 | D9: Aceptar o rechazar una solicitud pendiente. | E9: US-004 | F9: Must have | G9: 3
B10: US-006 | C10: EP-003 | D10: Marcar solicitud como entregada y descontar stock. | E10: US-005 | F10: Must have | G10: 4.5
B11: US-007 | C11: EP-003 | D11: Dar de alta manualmente una nueva pieza ficticia en el inventario. | E11: - | F11: Should have | G11: 7.5
B12: US-008 | C12: EP-003 | D12: Ajustar manualmente la cantidad de stock de una pieza. | E12: US-007 | F12: Should have | G12: 4.5
B13: US-009 | C13: EP-002 | D13: Cancelar una solicitud propia antes de ser gestionada por almacén. | E13: US-002 | F13: Should have | G13: 4.5
B14: US-010 | C14: EP-003 | D14: Añadir nota explicativa obligatoria al rechazar una solicitud. | E14: US-005 | F14: Should have | G14: 3
B15: US-011 | C15: EP-001 | D15: Filtrar catálogo de inventario por categoría de la pieza. | E15: US-001 | F15: Could have | G15: 3
B16: US-012 | C16: EP-001 | D16: Ordenar las piezas de inventario por cantidad de stock disponible. | E16: US-001 | F16: Could have | G16: 3
... B22: US-018 | C22: EP-004 | D22: Exportar el justificante de entrega de una solicitud a PDF. | E22: US-006 | F22: Won't have | G22: 6

Sheet Carga y Capacidad
A3: CENTINELA — Carga asignada por iteración y por persona
A4: La carga total de cada sprint se reparte entre el equipo en proporción a la capacidad efectiva de cada persona. El desglose exacto por tarea y persona se hará al planificar cada iteración en detalle.
A6: Iteración | B6: Carga asignada (h-p) | C6: Capacidad efectiva equipo (h-p) | D6: Jorge Acedo (PO) | E6: Sergio Jiménez (SM) | F6: Alfonso Canal (TL) | G6: Elena Cancho (QA/DevOps) | H6: Adolfo Lozano (Dev) | I6: Sobrecarga / Margen (h-p) | J6: Estado
A7: IT-001 | B7: =SUMIF(Coste!$E$8:$E$25, A7, Coste!$D$8:$D$25) -> 12 | C7: ='Capacidad del equipo'!$G$9 -> 15.5 | D7: =($B7 * 'Capacidad del equipo'!$G$4) / 'Capacidad del equipo'!$G$9 -> 1.9354839 | E7: =($B7 * 'Capacidad del equipo'!$G$5) / 'Capacidad del equipo'!$G$9 -> 1.9354839 | F7: =($B7 * 'Capacidad del equipo'!$G$6) / 'Capacidad del equipo'!$G$9 -> 2.3225806 | G7: =($B7 * 'Capacidad del equipo'!$G$7) / 'Capacidad del equipo'!$G$9 -> 2.7096774 | H7: =($B7 * 'Capacidad del equipo'!$G$8) / 'Capacidad del equipo'!$G$9 -> 3.0967742 | I7: =C7 - B7 -> 3.5 | J7: =IF(I7>=0, "OK", "SOBRECARGA") -> OK
A8: IT-002 | B8: =SUMIF(Coste!$E$8:$E$25, A8, Coste!$D$8:$D$25) -> 12 | C8: ='Capacidad del equipo'!$G$9 -> 15.5 | D8: =($B8 * 'Capacidad del equipo'!$G$4) / 'Capacidad del equipo'!$G$9 -> 1.9354839 | E8: =($B8 * 'Capacidad del equipo'!$G$5) / 'Capacidad del equipo'!$G$9 -> 1.9354839 | F8: =($B8 * 'Capacidad del equipo'!$G$6) / 'Capacidad del equipo'!$G$9 -> 2.3225806 | G8: =($B8 * 'Capacidad del equipo'!$G$7) / 'Capacidad del equipo'!$G$9 -> 2.7096774 | H8: =($B8 * 'Capacidad del equipo'!$G$8) / 'Capacidad del equipo'!$G$9 -> 3.0967742 | I8: =C8 - B8 -> 3.5 | J8: =IF(I8>=0, "OK", "SOBRECARGA") -> OK
A9: IT-003 | B9: =SUMIF(Coste!$E$8:$E$25, A9, Coste!$D$8:$D$25) -> 12 | C9: ='Capacidad del equipo'!$G$9 -> 15.5 | D9: =($B9 * 'Capacidad del equipo'!$G$4) / 'Capacidad del equipo'!$G$9 -> 1.9354839 | E9: =($B9 * 'Capacidad del equipo'!$G$5) / 'Capacidad del equipo'!$G$9 -> 1.9354839 | F9: =($B9 * 'Capacidad del equipo'!$G$6) / 'Capacidad del equipo'!$G$9 -> 2.3225806 | G9: =($B9 * 'Capacidad del equipo'!$G$7) / 'Capacidad del equipo'!$G$9 -> 2.7096774 | H9: =($B9 * 'Capacidad del equipo'!$G$8) / 'Capacidad del equipo'!$G$9 -> 3.0967742 | I9: =C9 - B9 -> 3.5 | J9: =IF(I9>=0, "OK", "SOBRECARGA") -> OK
A10: IT-004 | B10: =SUMIF(Coste!$E$8:$E$25, A10, Coste!$D$8:$D$25) -> 12 | C10: ='Capacidad del equipo'!$G$9 -> 15.5 | D10: =($B10 * 'Capacidad del equipo'!$G$4) / 'Capacidad del equipo'!$G$9 -> 1.9354839 | E10: =($B10 * 'Capacidad del equipo'!$G$5) / 'Capacidad del equipo'!$G$9 -> 1.9354839 | F10: =($B10 * 'Capacidad del equipo'!$G$6) / 'Capacidad del equipo'!$G$9 -> 2.3225806 | G10: =($B10 * 'Capacidad del equipo'!$G$7) / 'Capacidad del equipo'!$G$9 -> 2.7096774 | H10: =($B10 * 'Capacidad del equipo'!$G$8) / 'Capacidad del equipo'!$G$9 -> 3.0967742 | I10: =C10 - B10 -> 3.5 | J10: =IF(I10>=0, "OK", "SOBRECARGA") -> OK
A11: IT-005 | B11: =SUMIF(Coste!$E$8:$E$25, A11, Coste!$D$8:$D$25) -> 12 | C11: ='Capacidad del equipo'!$G$9 -> 15.5 | D11: =($B11 * 'Capacidad del equipo'!$G$4) / 'Capacidad del equipo'!$G$9 -> 1.9354839 | E11: =($B11 * 'Capacidad del equipo'!$G$5) / 'Capacidad del equipo'!$G$9 -> 1.9354839 | F11: =($B11 * 'Capacidad del equipo'!$G$6) / 'Capacidad del equipo'!$G$9 -> 2.3225806 | G11: =($B11 * 'Capacidad del equipo'!$G$7) / 'Capacidad del equipo'!$G$9 -> 2.7096774 | H11: =($B11 * 'Capacidad del equipo'!$G$8) / 'Capacidad del equipo'!$G$9 -> 3.0967742 | I11: =C11 - B11 -> 3.5 | J11: =IF(I11>=0, "OK", "SOBRECARGA") -> OK
A12: IT-006 | B12: =SUMIF(Coste!$E$8:$E$25, A12, Coste!$D$8:$D$25) -> 4.5 | C12: ='Capacidad del equipo'!$G$9 -> 15.5 | D12: =($B12 * 'Capacidad del equipo'!$G$4) / 'Capacidad del equipo'!$G$9 -> 0.72580645 | E12: =($B12 * 'Capacidad del equipo'!$G$5) / 'Capacidad del equipo'!$G$9 -> 0.72580645 | F12: =($B12 * 'Capacidad del equipo'!$G$6) / 'Capacidad del equipo'!$G$9 -> 0.87096774 | G12: =($B12 * 'Capacidad del equipo'!$G$7) / 'Capacidad del equipo'!$G$9 -> 1.016129 | H12: =($B12 * 'Capacidad del equipo'!$G$8) / 'Capacidad del equipo'!$G$9 -> 1.1612903 | I12: =C12 - B12 -> 11 | J12: =IF(I12>=0, "OK", "SOBRECARGA") -> OK
A13: TOTAL PROYECTO | B13: 64.5 | C13: 93 | D13: =SUM(D7:D12) -> 10.403226 | E13: =SUM(E7:E12) -> 10.403226 | F13: =SUM(F7:F12) -> 12.483871 | G13: =SUM(G7:G12) -> 14.564516 | H13: =SUM(H7:H12) -> 16.645161 | I13: 28.5
A15: Trabajo sin asignar a Release 1 (h-p) | C15: 24
A16: Margen total disponible (6 sprints, h-p) | C16: 28.5

Sheet Coste
B3: CENTINELA — Cálculo de coste
B4: Coste = esfuerzo (h-p) × tarifa media ponderada del equipo (hoja Capacidad). Ver supuesto de tarifas allí.
B6: Coste por historia de usuario
B7: {=SUMIF(Coste!$E$8:$E$25, Coste!E5A7, Coste!$D$8:$D$25)} -> 0 | C7: Épica | D7: Estimación (h-p) | E7: Iteración | F7: Coste (€)
B8: ='Product Backlog'!B5 -> US-001 | C8: ='Product Backlog'!C5 -> EP-001 | D8: ='Product Backlog'!G5 -> 4.5 | E8: IT-001 | F8: =D8 * 'Capacidad del equipo'!$C$26 -> 148.64516
B9: ='Product Backlog'!B6 -> US-002 | C9: ='Product Backlog'!C6 -> EP-002 | D9: ='Product Backlog'!G6 -> 7.5 | E9: IT-001 | F9: =D9 * 'Capacidad del equipo'!$C$26 -> 247.74194
B10: ='Product Backlog'!B7 -> US-003 | C10: ='Product Backlog'!C7 -> EP-004 | D10: ='Product Backlog'!G7 -> 4.5 | E10: IT-002 | F10: =D10 * 'Capacidad del equipo'!$C$26 -> 148.64516
B11: ='Product Backlog'!B8 -> US-004 | C11: ='Product Backlog'!C8 -> EP-003 | D11: ='Product Backlog'!G8 -> 4.5 | E11: IT-002 | F11: =D11 * 'Capacidad del equipo'!$C$26 -> 148.64516
B12: ='Product Backlog'!B9 -> US-005 | C12: ='Product Backlog'!C9 -> EP-003 | D12: ='Product Backlog'!G9 -> 3 | E12: IT-002 | F12: =D12 * 'Capacidad del equipo'!$C$26 -> 99.096774
B13: ='Product Backlog'!B10 -> US-006 | C13: ='Product Backlog'!C10 -> EP-003 | D13: ='Product Backlog'!G10 -> 4.5 | E13: IT-003 | F13: =D13 * 'Capacidad del equipo'!$C$26 -> 148.64516
B14: ='Product Backlog'!B11 -> US-007 | C14: ='Product Backlog'!C11 -> EP-003 | D14: ='Product Backlog'!G11 -> 7.5 | E14: IT-003 | F14: =D14 * 'Capacidad del equipo'!$C$26 -> 247.74194
B15: ='Product Backlog'!B12 -> US-008 | C15: ='Product Backlog'!C12 -> EP-003 | D15: ='Product Backlog'!G12 -> 4.5 | E15: IT-004 | F15: =D15 * 'Capacidad del equipo'!$C$26 -> 148.64516
B16: ='Product Backlog'!B13 -> US-009 | C16: ='Product Backlog'!C13 -> EP-002 | D16: ='Product Backlog'!G13 -> 4.5 | E16: IT-004 | F16: =D16 * 'Capacidad del equipo'!$C$26 -> 148.64516
B17: ='Product Backlog'!B14 -> US-010 | C17: ='Product Backlog'!C14 -> EP-003 | D17: ='Product Backlog'!G14 -> 3 | E17: IT-004 | F17: =D17 * 'Capacidad del equipo'!$C$26 -> 99.096774
B18: ='Product Backlog'!B15 -> US-011 | C18: ='Product Backlog'!C15 -> EP-001 | D18: ='Product Backlog'!G15 -> 3 | E18: IT-005 | F18: =D18 * 'Capacidad del equipo'!$C$26 -> 99.096774
B19: ='Product Backlog'!B16 -> US-012 | C19: ='Product Backlog'!C16 -> EP-001 | D19: ='Product Backlog'!G16 -> 3 | E19: IT-005 | F19: =D19 * 'Capacidad del equipo'!$C$26 -> 99.096774
B20: ='Product Backlog'!B17 -> US-013 | C20: ='Product Backlog'!C17 -> EP-004 | D20: ='Product Backlog'!G17 -> 6 | E20: IT-005 | F20: =D20 * 'Capacidad del equipo'!$C$26 -> 198.19355 | K20: ¡
B21: ='Product Backlog'!B18 -> US-014 | C21: ='Product Backlog'!C18 -> EP-002 | D21: ='Product Backlog'!G18 -> 4.5 | E21: IT-006 | F21: =D21 * 'Capacidad del equipo'!$C$26 -> 148.64516
B22: ='Product Backlog'!B19 -> US-015 | C22: ='Product Backlog'!C19 -> EP-003 | D22: ='Product Backlog'!G19 -> 3 | E22: Sin planificar | F22: =D22 * 'Capacidad del equipo'!$C$26 -> 99.096774
B23: ='Product Backlog'!B20 -> US-016 | C23: ='Product Backlog'!C20 -> EP-004 | D23: ='Product Backlog'!G20 -> 7.5 | E23: Sin planificar | F23: =D23 * 'Capacidad del equipo'!$C$26 -> 247.74194
B24: ='Product Backlog'!B21 -> US-017 | C24: ='Product Backlog'!C21 -> EP-001 | D24: ='Product Backlog'!G21 -> 7.5 | E24: Sin planificar | F24: =D24 * 'Capacidad del equipo'!$C$26 -> 247.74194
B25: ='Product Backlog'!B22 -> US-018 | C25: ='Product Backlog'!C22 -> EP-004 | D25: ='Product Backlog'!G22 -> 6 | E25: Sin planificar | F25: =D25 * 'Capacidad del equipo'!$C$26 -> 198.19355
E26: TOTAL CATÁLOGO | F26: =SUM(F8:F25) -> 2923.3548
E27: TOTAL PLANIFICADO Release 1 | F27: =SUMIFS(F8:F25, E8:E25, "<>Sin planificar") -> 2130.5806
B30: Coste por persona (Release 1, 6 sprints)
B31: Miembro (Rol) | C31: Carga total asignada (h-p) | D31: Tarifa (€/h-p) | E31: Coste (€)
B32: Jorge Acedo (PO) | C32: ='Carga y Capacidad'!D13 -> 10.403226 | D32: ='Capacidad del equipo'!C20 -> 32 | E32: =C32 * D32 -> 332.90323
B33: Sergio Jiménez (SM) | C33: ='Carga y Capacidad'!E13 -> 10.403226 | D33: ='Capacidad del equipo'!C21 -> 30 | E33: =C33 * D33 -> 312.09677
B34: Alfonso Canal (TL) | C34: ='Carga y Capacidad'!F13 -> 12.483871 | D34: ='Capacidad del equipo'!C22 -> 42 | E34: =C34 * D34 -> 524.32258
B35: Elena Cancho (QA/DevOps) | C35: ='Carga y Capacidad'!G13 -> 14.564516 | D35: ='Capacidad del equipo'!C23 -> 34 | E35: =C35 * D35 -> 495.19355
B36: Adolfo Lozano (Dev) | C36: ='Carga y Capacidad'!H13 -> 16.645161 | D36: ='Capacidad del equipo'!C24 -> 28 | E36: =C36 * D36 -> 466.06452
B37: TOTAL | C37: =SUM(C32:C36) -> 64.5 | D37: =SUM(D32:D36) -> 166 | E37: =SUM(E32:E36) -> 2130.5806
B39: Comprobación (coste por historia = coste por persona)
B42: Coste por iteración (sprint)
B43: Iteración | C43: Carga (h-p) | D43: Coste (€)
B44: IT-001 | C44: =SUMIFS($D$8:$D$25, $E$8:$E$25, B44) -> 12 | D44: =SUMIFS($F$8:$F$25, $E$8:$E$25, B44) -> 396.3871
B45: IT-002 | C45: =SUMIFS($D$8:$D$25, $E$8:$E$25, B45) -> 12 | D45: =SUMIFS($F$8:$F$25, $E$8:$E$25, B45) -> 396.3871
B46: IT-003 | C46: =SUMIFS($D$8:$D$25, $E$8:$E$25, B46) -> 12 | D46: =SUMIFS($F$8:$F$25, $E$8:$E$25, B46) -> 396.3871
B47: IT-004 | C47: =SUMIFS($D$8:$D$25, $E$8:$E$25, B47) -> 12 | D47: =SUMIFS($F$8:$F$25, $E$8:$E$25, B47) -> 396.3871
B48: IT-005 | C48: =SUMIFS($D$8:$D$25, $E$8:$E$25, B48) -> 12 | D48: =SUMIFS($F$8:$F$25, $E$8:$E$25, B48) -> 396.3871
...

Sheet Viabilidad
B4: CENTINELA — Análisis de viabilidad (Release 1)
B6: Capacidad efectiva equipo / sprint (h-p) | C6: ='Capacidad del equipo'!G9 -> 15.5
B7: Nº de sprints (6 semanas de ejecución real) | C7: 6
B8: Capacidad efectiva TOTAL del proyecto (h-p) | C8: =C6 * C7 -> 93
B9: Esfuerzo Must+Should have (núcleo, h-p) | C9: =SUMIF('Product Backlog'!F:F, "*Must have*", 'Product Backlog'!G:G) + SUMIF('Product Backlog'!F:F, "*Should have*", 'Product Backlog'!G:G) -> 48
B10: Esfuerzo total planificado Release 1 (h-p) | C10: =SUMIFS(Coste!$D$8:$D$25, Coste!$E$8:$E$25, "<>Sin planificar") -> 64.5
B11: Esfuerzo diferido (Could/Won't sin planificar, h-p) | C11: =SUMIF(Coste!E:E, "Sin planificar", Coste!D:D) -> 24
B12: Margen disponible (h-p) | C12: =C8 - C10 -> 28.5
B13: % de capacidad utilizada (Release 1) | C13: =C10 / C8 -> 0.69354839
B14: Sprints necesarios para el núcleo (Must+Should) | C14: =C9 / C6 -> 3.0967742
B15: Coste total estimado del proyecto (Release 1) | C15: =Coste!F27 -> 2130.5806
B18: Veredicto de viabilidad
B19: VIABLE: la carga planificada no supera la capacidad efectiva del equipo en ningún sprint. Margen de 28.5 h-p (31% de la capacidad total) para imprevistos, refinar historias Could have o absorber retrasos.
